Traceback (most recent call last):
  File "/usr/local/lib/python3.10/dist-packages/jupyter_cache/executors/utils.py", line 58, in single_nb_execution
    executenb(
  File "/usr/local/lib/python3.10/dist-packages/nbclient/client.py", line 1305, in execute
    return NotebookClient(nb=nb, resources=resources, km=km, **kwargs).execute()
  File "/usr/local/lib/python3.10/dist-packages/jupyter_core/utils/__init__.py", line 173, in wrapped
    return loop.run_until_complete(inner)
  File "/usr/lib/python3.10/asyncio/base_events.py", line 649, in run_until_complete
    return future.result()
  File "/usr/local/lib/python3.10/dist-packages/nbclient/client.py", line 705, in async_execute
    await self.async_execute_cell(
  File "/usr/local/lib/python3.10/dist-packages/nbclient/client.py", line 1058, in async_execute_cell
    await self._check_raise_for_error(cell, cell_index, exec_reply)
  File "/usr/local/lib/python3.10/dist-packages/nbclient/client.py", line 914, in _check_raise_for_error
    raise CellExecutionError.from_cell_and_msg(cell, exec_reply_content)
nbclient.exceptions.CellExecutionError: An error occurred while executing the following cell:
------------------
import seaborn as sns
import matplotlib.pyplot as plt
sns.FacetGrid(df, hue="Classification",size =7).map(plt.scatter, "Age", "BMI").add_legend()

------------------


[0;31m---------------------------------------------------------------------------[0m
[0;31mTypeError[0m                                 Traceback (most recent call last)
[0;32m<ipython-input-12-069ff47c5cfc>[0m in [0;36m<cell line: 3>[0;34m()[0m
[1;32m      1[0m [0;32mimport[0m [0mseaborn[0m [0;32mas[0m [0msns[0m[0;34m[0m[0;34m[0m[0m
[1;32m      2[0m [0;32mimport[0m [0mmatplotlib[0m[0;34m.[0m[0mpyplot[0m [0;32mas[0m [0mplt[0m[0;34m[0m[0;34m[0m[0m
[0;32m----> 3[0;31m [0msns[0m[0;34m.[0m[0mFacetGrid[0m[0;34m([0m[0mdf[0m[0;34m,[0m [0mhue[0m[0;34m=[0m[0;34m"Classification"[0m[0;34m,[0m[0msize[0m [0;34m=[0m[0;36m7[0m[0;34m)[0m[0;34m.[0m[0mmap[0m[0;34m([0m[0mplt[0m[0;34m.[0m[0mscatter[0m[0;34m,[0m [0;34m"Age"[0m[0;34m,[0m [0;34m"BMI"[0m[0;34m)[0m[0;34m.[0m[0madd_legend[0m[0;34m([0m[0;34m)[0m[0;34m[0m[0;34m[0m[0m
[0m
[0;31mTypeError[0m: FacetGrid.__init__() got an unexpected keyword argument 'size'

